Traceback (most recent call last):
  File "/home/ywatanabe/proj/siEEG_ripple_dev/utils/load/nix_2_csv_and_pkl.py", line 356, in <module>
    main()
  File "/home/ywatanabe/proj/siEEG_ripple_dev/utils/load/nix_2_csv_and_pkl.py", line 54, in main
    f = h5py.File(fpath, "r+")
  File "/usr/local/lib64/python3.9/site-packages/h5py/_hl/files.py", line 562, in __init__
    fid = make_fid(name, mode, userblock_size, fapl, fcpl, swmr=swmr)
  File "/usr/local/lib64/python3.9/site-packages/h5py/_hl/files.py", line 237, in make_fid
    fid = h5f.open(name, h5f.ACC_RDWR, fapl=fapl)
  File "h5py/_objects.pyx", line 54, in h5py._objects.with_phil.wrapper
  File "h5py/_objects.pyx", line 55, in h5py._objects.with_phil.wrapper
  File "h5py/h5f.pyx", line 102, in h5py.h5f.open
FileNotFoundError: [Errno 2] Unable to synchronously open file (unable to open file: name = './data/data_nix/Data_Subject_08_Session_04.h5', errno = 2, error message = 'No such file or directory', flags = 1, o_flags = 2)
